Workbook

Sheet PILETAS
A1: ID_PILETA | B1: Capacidad | C1: Lote Pta | D1: Estado | E1: Tipo | F1: Lts_x_cm
A2: 1 | B2: 107500 | E2: EST | F2: 574
A3: 2 | B3: 8400 | C3: da997936 | E3: EST | F3: 43
A4: 3 | B4: 15000 | E4: EST | F4: 78
A5: 4 | B5: 26000 | E5: EST | F5: 127
A6: 5 | B6: 30000 | C6: ebf08055 | E6: EST | F6: 170
A7: 6 | B7: 32000 | C7: a324303d | E7: EST | F7: 170
A8: 7 | B8: 30000 | E8: EST | F8: 170
A9: 8 | B9: 22000 | C9: 376dbee6 | E9: EST | F9: 130
A10: 9 | B10: 30000 | E10: EST | F10: 170
A11: 10 | B11: 21000 | C11: f9bf68a3 | E11: EST | F11: 132
A12: 11 | B12: 36000 | E12: EST | F12: 190
A13: 12 | B13: 35300 | E13: EST | F13: 190
A14: 13 | B14: 20000 | E14: EST | F14: 145
A15: 14 | B15: 37000 | C15: 10b87434 | E15: EST | F15: 201
A16: 15 | B16: 36500 | E16: EST | F16: 197
A17: 16 | B17: 19500 | C17: 869e8a1b | E17: EST | F17: 137
A18: 17 | B18: 39500 | E18: EST | F18: 200
A19: 18 | B19: 39500 | E19: EST | F19: 200
A20: 19 | B20: 27500 | E20: EST | F20: 139
A21: 20 | B21: 38100 | E21: EST | F21: 175
A22: 21 | B22: 28000 | E22: EST | F22: 137
A23: 22 | B23: 41100 | E23: EST | F23: 205
A24: 23 | B24: 197100 | E24: EST | F24: 564
A25: 24 | B25: 186600 | C25: b3a40361 | E25: EST | F25: 550
A26: 25 | B26: 194300 | C26: a2728d01 | E26: EST | F26: 560
A27: 26 | B27: 207600 | C27: a37dae6b | E27: EST | F27: 600
A28: 27 | B28: 207100 | E28: EST | F28: 600
A29: 28 | B29: 216000 | E29: EST | F29: 600
A30: 29 | B30: 20400 | E30: EST | F30: 113
A31: 30 | B31: 38800 | E31: EST | F31: 170
A32: 31 | B32: 25700 | E32: EST | F32: 133
A33: 32 | B33: 36300 | E33: EST | F33: 180
A34: 33 | B34: 25300 | C34: 7def2139 | E34: EST | F34: 138
A35: 34 | B35: 39500 | C35: 08cd1438 | E35: EST | F35: 200
A36: 35 | B36: 39300 | E36: EST | F36: 200
A37: 36 | B37: 19700 | C37: 0997a77d | E37: EST | F37: 120
A38: 37 | B38: 39000 | E38: EST | F38: 200
A39: 38 | B39: 23500 | E39: EST | F39: 130
A40: 39 | B40: 40000 | E40: EST | F40: 200
...

Sheet SQL_GENERADO_V2
A1: -- 1. TABLA: Estado_pileta
A3: INSERT INTO Estado_pileta (nombre) VALUES ('ACTIVO');
A5: -- 2. TABLA: Tipo_movimiento
A7: INSERT INTO Tipo_movimiento (nombre) VALUES ('Trasiego');
A8: INSERT INTO Tipo_movimiento (nombre) VALUES ('Ajuste Volumen');
A9: INSERT INTO Tipo_movimiento (nombre) VALUES ('Llenado');
A11: -- 3. TABLA: Variedad
A13: INSERT INTO Variedad (nombre, descripcion) VALUES ('Syrah', NULL);
A14: INSERT INTO Variedad (nombre, descripcion) VALUES ('Malbec', NULL);
A15: INSERT INTO Variedad (nombre, descripcion) VALUES ('Merlot', NULL);
A16: INSERT INTO Variedad (nombre, descripcion) VALUES ('Malbec Syrah', NULL);
A17: INSERT INTO Variedad (nombre, descripcion) VALUES ('Ajuste Volumen', NULL);
... A3201: -- FIN DEL SCRIPT

Sheet CALIFICACION VINO
A1: Calificacion
A2: 1+
A3: 1
A4: 1-
A5: 2+
A6: 2
A7: 2-
A8: 3+
A9: 3
A10: 3-

Sheet Trazado
A1: Pileta a trazar | B1: 83
A2: PILETA
A3: =IFERROR(__xludf.DUMMYFUNCTION("query(PILETAS!A1:D132,""SELECT * WHERE A=""&B1,1)"),"ID_PILETA") -> ID_PILETA | B3: =IFERROR(__xludf.DUMMYFUNCTION("""COMPUTED_VALUE"""),"Capacidad") -> Capacidad | C3: =IFERROR(__xludf.DUMMYFUNCTION("""COMPUTED_VALUE"""),"Lote Pta") -> Lote Pta | D3: =IFERROR(__xludf.DUMMYFUNCTION("""COMPUTED_VALUE"""),"Estado") -> Estado
A4: =IFERROR(__xludf.DUMMYFUNCTION("""COMPUTED_VALUE"""),83.0) -> 83 | B4: =IFERROR(__xludf.DUMMYFUNCTION("""COMPUTED_VALUE"""),81500.0) -> 81500 | C4: =IFERROR(__xludf.DUMMYFUNCTION("""COMPUTED_VALUE"""),"32396d27") -> 32396d27
A6: LOTE
A7: =IFERROR(__xludf.DUMMYFUNCTION("QUERY('PILETAS LOTES'!A1:L1001,""SELECT * WHERE A='""&C4&""'"",1)"),"ID Lote Pileta") -> ID Lote Pileta | B7: =IFERROR(__xludf.DUMMYFUNCTION("""COMPUTED_VALUE"""),"Lotes Origen") -> Lotes Origen | C7: =IFERROR(__xludf.DUMMYFUNCTION("""COMPUTED_VALUE"""),"DateTime") -> DateTime | D7: =IFERROR(__xludf.DUMMYFUNCTION("""COMPUTED_VALUE"""),"Pileta Nro") -> Pileta Nro | E7: =IFERROR(__xludf.DUMMYFUNCTION("""COMPUTED_VALUE"""),"Capacidad") -> Capacidad | F7: =IFERROR(__xludf.DUMMYFUNCTION("""COMPUTED_VALUE"""),"Variedad") -> Variedad | G7: =IFERROR(__xludf.DUMMYFUNCTION("""COMPUTED_VALUE"""),"Cantidad Inicial") -> Cantidad Inicial | H7: =IFERROR(__xludf.DUMMYFUNCTION("""COMPUTED_VALUE"""),"Cantidad Actual") -> Cantidad Actual | I7: =IFERROR(__xludf.DUMMYFUNCTION("""COMPUTED_VALUE"""),"Observaciones Lote") -> Observaciones Lote | J7: =IFERROR(__xludf.DUMMYFUNCTION("""COMPUTED_VALUE"""),"CIU") -> CIU | K7: =IFERROR(__xludf.DUMMYFUNCTION("""COMPUTED_VALUE"""),"Estado") -> Estado | L7: =IFERROR(__xludf.DUMMYFUNCTION("""COMPUTED_VALUE"""),"Califiacion Vino") -> Califiacion Vino
A10: MOVIMIENTOS QUE DIERON ORIGEN A ESTE LOTE
A11: =IFERROR(__xludf.DUMMYFUNCTION("QUERY(MOVIMIENTO!A1:R1001,""SELECT * WHERE L='""&A8&""'"",1)"),"#REF!") -> #REF!
A14: LOTES DE PILETAS QUE FORMAN PARTE DE ESTE MOVIMIENTO
A15: =IFERROR(__xludf.DUMMYFUNCTION("QUERY('PILETAS LOTES'!A1:L1001,""SELECT * WHERE A='""&C12&""' OR A='""&H12&""'"" ,1)"),"ID Lote Pileta") -> ID Lote Pileta | B15: =IFERROR(__xludf.DUMMYFUNCTION("""COMPUTED_VALUE"""),"Lotes Origen") -> Lotes Origen | C15: =IFERROR(__xludf.DUMMYFUNCTION("""COMPUTED_VALUE"""),"DateTime") -> DateTime | D15: =IFERROR(__xludf.DUMMYFUNCTION("""COMPUTED_VALUE"""),"Pileta Nro") -> Pileta Nro | E15: =IFERROR(__xludf.DUMMYFUNCTION("""COMPUTED_VALUE"""),"Capacidad") -> Capacidad | F15: =IFERROR(__xludf.DUMMYFUNCTION("""COMPUTED_VALUE"""),"Variedad") -> Variedad | G15: =IFERROR(__xludf.DUMMYFUNCTION("""COMPUTED_VALUE"""),"Cantidad Inicial") -> Cantidad Inicial | H15: =IFERROR(__xludf.DUMMYFUNCTION("""COMPUTED_VALUE"""),"Cantidad Actual") -> Cantidad Actual | I15: =IFERROR(__xludf.DUMMYFUNCTION("""COMPUTED_VALUE"""),"Observaciones Lote") -> Observaciones Lote | J15: =IFERROR(__xludf.DUMMYFUNCTION("""COMPUTED_VALUE"""),"CIU") -> CIU | K15: =IFERROR(__xludf.DUMMYFUNCTION("""COMPUTED_VALUE"""),"Estado") -> Estado | L15: =IFERROR(__xludf.DUMMYFUNCTION("""COMPUTED_VALUE"""),"Califiacion Vino") -> Califiacion Vino

Sheet PILETAS LOTES
A1: ID Lote Pileta | B1: Lotes Origen | C1: DateTime | D1: Pileta Nro | E1: Capacidad | F1: Variedad | G1: Cantidad Inicial | H1: Cantidad Actual | I1: Observaciones Lote | J1: CIU | K1: Estado | L1: Califiacion Vino | M1: Color
A2: 04b35bd0 | C2: 45703 | D2: 2 | E2: 12500 | F2: Syrah | G2: 12500 | H2: 12500 | M2: Tinto
A3: 51d6bbdd | C3: 45703 | D3: 3 | E3: 14000 | F3: Malbec | H3: 14000
A4: 6cde19b3 | C4: 45703 | D4: 6 | E4: 69750 | F4: Merlot | H4: 69750
A5: 348ea8a7 | B5: 04b35bd0 | C5: 45703 | D5: 7 | E5: 85000 | F5: Syrah | H5: 12500
A6: 8c336568 | B6: 51d6bbdd, 348ea8a7 | C6: 45703 | D6: 7 | E6: 85000 | F6: Malbec Syrah | G6: 12500 | H6: 26500
A7: a1c20159 | B7: 8c336568 | C7: 45704 | D7: 5 | E7: 52000 | F7: Malbec Syrah | G7: 0 | H7: 26500
A8: c63f7bed | B8: a1c20159 | C8: 45704.938 | D8: 79 | E8: 26000 | F8: Malbec Syrah | G8: 0 | H8: 26000
A9: d13652cf | B9: 6cde19b3 | C9: 45704.947 | D9: 30 | E9: 38800 | F9: Merlot | G9: 0 | H9: 37750
A10: b27a5ea7 | C10: 45704.951 | D10: 1 | E10: 107500 | F10: Ajuste Volumen | H10: 107500
A11: 58b123c6 | B11: 6cde19b3 | C11: 45704.967 | D11: 11 | E11: 36000 | F11: Merlot | G11: 0 | H11: 32000
A12: 53f98d96 | B12: a1c20159, 58b123c6 | C12: 45704.969 | D12: 11 | E12: 36000 | F12: Merlot | G12: 32000 | H12: 32500
A13: ce475c91 | B13: b27a5ea7, d13652cf | C13: 45704.97 | D13: 30 | E13: 38800 | F13: Ajuste Volumen | G13: 37750 | H13: 37800
A14: cedc0dc0 | C14: 45705.533 | D14: 77 | E14: 26000 | F14: Chardonnay | H14: 25000 | K14: Fermentando
A15: 868560b2 | C15: 45705.534 | D15: 80 | E15: 26100 | F15: Aspirant Ferm 25 | H15: 12000 | J15: 5765 , 5766
A16: 5eb33d17 | C16: 45705.534 | D16: 81 | E16: 26500 | F16: Syrah Ferm 25 | H16: 8000 | J16: 5790
A17: 7c1795fa | C17: 45705.535 | D17: 82 | E17: 42600 | F17: Merlot Ferm 25 | H17: 20000 | J17: 5780 , 5782 , 5783
A18: 7366c02e | C18: 45705.535 | D18: 65 | E18: 35500 | F18: Merlot Ferm 25 | H18: 15000 | J18: 5784 , 5785 , 5786 , 5788
A19: 0632409f | C19: 45705.535 | D19: 83 | E19: 81500 | F19: Malbec Ferm 25 | H19: 30000 | J19: 5770 , 5772 , 5774 , 5775 , 5777 , 5778
A20: 24b66da0 | C20: 45705.536 | D20: 84 | E20: 83000 | F20: Aspirant Ferm 25 | H20: 30000 | J20: 5761 , 5762 , 5763 , 5764
A21: e323890c | C21: 45705.536 | D21: 85 | E21: 84000 | F21: Aspirant Anccelota Ferm | H21: 40000 | J21: 5767 , 5768 , 5769 , 5771 , 5773 , 5776 , 5779 , 5781
A23: c76dfce1 | C23: 45691.827 | D23: 86 | E23: 88000 | F23: Aspirant | H23: 42000 | J23: 5760 , 5756 , 5757 , 5758 , 5759
A24: f6f9d651 | C24: 45708.712 | D24: 88 | E24: 78900 | F24: Merlot | H24: 28000 | J24: 5792 , 5796 , 5797 , 5800
A25: 0835b42b | B25: c76dfce1 | C25: 45708.716 | D25: 102 | E25: 31000 | F25: Aspirant | G25: 0 | H25: 30000 | I25: Vino al c9rte de la vendimia | K25: Descubada
A26: 903e1ab8 | B26: 24b66da0 | C26: 45708.725 | D26: 103 | E26: 31000 | F26: Aspirant | G26: 0 | H26: 15000
A27: 65eb8fac | B27: 5eb33d17, c76dfce1 | C27: 45708.743 | D27: 86 | E27: 88000 | F27: Syrah s/Asp | G27: 12000 | H27: 20000
A28: 13b5f72f | B28: 7c1795fa, 65eb8fac | C28: 45708.748 | D28: 86 | E28: 88000 | F28: Syrah Merlot s/Asp | G28: 20000 | H28: 40000
A29: 3c569c0a | B29: 7366c02e, 24b66da0 | C29: 45708.751 | D29: 84 | E29: 83000 | F29: Merlot s/Asp | G29: 15000 | H29: 30000
A30: d7af693c | B30: 0632409f | C30: 45708.752 | D30: 104 | E30: 31000 | F30: Malbec Gota | G30: 0 | H30: 29000 | K30: Descubada
A31: 1749cd27 | B31: 0632409f | C31: 45708.754 | D31: 105 | E31: 31000 | F31: Malbec Prensa | G31: 0 | H31: 5000
A32: 5008e5a3 | C32: 45708.794 | D32: 11 | E32: 36000 | F32: Cabernet Sauv Rect | H32: 36000 | K32: Rectificado
A33: 27abb7ee | C33: 45708.794 | D33: 16 | E33: 19500 | F33: Cabernet Sauvignon Rect | H33: 19500 | K33: Rectificado
A34: eec28962 | C34: 45708.795 | D34: 30 | E34: 38800 | F34: Aspirant 24 | H34: 38800 | K34: Terminado | M34: Tinto
A35: 30d0ce51 | C35: 45708.795 | D35: 41 | E35: 35100 | F35: Cabernet Sauvignon Rect 24 | H35: 35100 | K35: Rectificado
A36: 73b50dc4 | C36: 45708.797 | D36: 42 | E36: 35900 | F36: Malbec 24 | H36: 35900 | K36: Terminado
A37: d5c7ee63 | C37: 45708.798 | D37: 44 | E37: 19100 | F37: Cabernet Sauvignon Rect 24 | H37: 19100 | K37: Rectificado
A38: 241b642a | C38: 45708.799 | D38: 45 | E38: 30000 | F38: Bonarda 24 Rect | H38: 30000 | K38: Rectificado
A39: 665bbad3 | C39: 45708.799 | D39: 47 | E39: 20000 | F39: Cabernet Sauvignon 24 Rect | H39: 20000 | K39: Rectificado
A40: d9821c78 | C40: 45708.799 | D40: 48 | E40: 26000 | F40: Bonarda 24 Rect | H40: 26000 | K40: Rectificado
A41: a9ae339e | C41: 45708.799 | D41: 49 | E41: 26000 | F41: Bonarda 24 Rect | H41: 26000 | K41: Rectificado
...

Sheet MOVIMIENTO
A1: ID_Movimiento | B1: Date_Time | C1: Lote Origen | D1: Pileta Origen | E1: Variedad Origen | F1: Volumen Trasegado | G1: Pileta Destino | H1: Lote Destino Original | I1: Variedad Destino Original | J1: Volumen Destino Original | K1: Volumen Destino Final | L1: Lote Destino Final | M1: Variedad Destino Final | N1: Observaciones Movimiento | O1: Pileta Origen Estado | P1: Pileta Destino Estado | Q1: Copiar Estado Destino | R1: Pileta Destino Final Estado | S1: Calificacion Origen | T1: Calificacion Destino | U1: Calificacion Destino Final
A2: de764408 | B2: 45703.876 | C2: 04b35bd0 | D2: 2 | E2: Syrah | F2: 12500 | G2: 7 | K2: 12500 | L2: 348ea8a7 | M2: Syrah
A3: 6596058d | B3: 45703.876 | C3: 51d6bbdd | D3: 3 | E3: Malbec | F3: 14000 | G3: 7 | H3: 348ea8a7 | I3: Syrah | J3: 12500 | K3: 26500 | L3: 8c336568 | M3: Malbec Syrah
A4: ea75ff40 | B4: 45704.903 | C4: 8c336568 | D4: 7 | E4: Malbec Syrah | F4: 26500 | G4: 5 | J4: 0 | K4: 26500 | L4: a1c20159 | M4: Malbec Syrah
A5: 12e4e13b | B5: 45704.937 | C5: a1c20159 | D5: 5 | E5: Malbec Syrah | F5: 26000 | G5: 79 | J5: 0 | K5: 26000 | L5: c63f7bed | M5: Malbec Syrah
A6: 14c84b1e | B6: 45704.946 | C6: 6cde19b3 | D6: 6 | E6: Merlot | F6: 37750 | G6: 30 | J6: 0 | K6: 37750 | L6: d13652cf | M6: Merlot
A8: db9bd61e | B8: 45704.967 | C8: 6cde19b3 | D8: 6 | E8: Merlot | F8: 32000 | G8: 11 | J8: 0 | K8: 32000 | L8: 58b123c6 | M8: Merlot
A9: 405705de | B9: 45704.968 | C9: a1c20159 | D9: 5 | E9: Malbec Syrah | F9: 500 | G9: 11 | H9: 58b123c6 | I9: Merlot | J9: 32000 | K9: 32500 | L9: 53f98d96 | M9: Merlot
A10: 345b4c91 | B10: 45704.97 | C10: b27a5ea7 | D10: 1 | E10: Ajuste Volumen | F10: 50 | G10: 30 | H10: d13652cf | I10: Merlot | J10: 37750 | K10: 37800 | L10: ce475c91 | M10: Ajuste Volumen
A11: cdf62189 | B11: 45708.714 | C11: c76dfce1 | D11: 86 | E11: Aspirant | F11: 30000 | G11: 102 | J11: 0 | K11: 30000 | L11: 0835b42b | M11: Aspirant | N11: Descube
A12: 14a9777e | B12: 45708.725 | C12: 24b66da0 | D12: 84 | E12: Aspirant Ferm 25 | F12: 15000 | G12: 103 | J12: 0 | K12: 15000 | L12: 903e1ab8 | M12: Aspirant | N12: Descube Gota
A13: ee927519 | B13: 45708.741 | C13: 5eb33d17 | D13: 81 | E13: Syrah Ferm 25 | F13: 8000 | G13: 86 | H13: c76dfce1 | I13: Aspirant | J13: 12000 | K13: 20000 | L13: 65eb8fac | M13: Syrah s/Asp | N13: Descube gota y prensa a Aspirant
A14: 6f1c07ae | B14: 45708.747 | C14: 7c1795fa | D14: 82 | E14: Merlot Ferm 25 | F14: 20000 | G14: 86 | H14: 65eb8fac | I14: Syrah s/Asp | J14: 20000 | K14: 40000 | L14: 13b5f72f | M14: Syrah Merlot s/Asp | N14: Descube gota y prensa
A15: 662b2483 | B15: 45708.75 | C15: 7366c02e | D15: 65 | E15: Merlot Ferm 25 | F15: 15000 | G15: 84 | H15: 24b66da0 | I15: Aspirant Ferm 25 | J15: 15000 | K15: 30000 | L15: 3c569c0a | M15: Merlot s/Asp | N15: Descube Gota y prensa sobre Aspirant
A16: 9f189d7d | B16: 45708.752 | C16: 0632409f | D16: 83 | E16: Malbec Ferm 25 | F16: 25000 | G16: 104 | J16: 0 | K16: 29000 | L16: d7af693c | M16: Malbec Gota | N16: Descube Gota
A17: cfa35761 | B17: 45708.753 | C17: 0632409f | D17: 83 | E17: Malbec Ferm 25 | F17: 5000 | G17: 105 | J17: 0 | K17: 5000 | L17: 1749cd27 | M17: Malbec Prensa | N17: Malbec descubado a prensa
A18: 968706bd | B18: 45709.814 | C18: f6f9d651 | D18: 88 | E18: Merlot | F18: 10000 | G18: 80 | H18: 868560b2 | I18: Aspirant Ferm 25 | J18: 12000 | K18: 22000 | L18: d6272af5 | M18: Merlot s/ Asp
A19: 8dbab148 | B19: 45709.836 | C19: e323890c | D19: 85 | E19: Aspirant Anccelota Ferm | F19: 30000 | G19: 107 | J19: 0 | K19: 30000 | L19: 0aa8c362 | M19: Aspirant Anccelota Gota | N19: Sin prensar pileta origen para recargar
A20: 7039bd57 | B20: 45709.837 | C20: f6f9d651 | D20: 88 | E20: Merlot | F20: 18000 | G20: 85 | H20: e323890c | I20: Aspirant Anccelota Ferm | J20: 10000 | K20: 28000 | L20: f8624f14 | M20: Merlot s/Asp | N20: Gota y Prensa sobre Aspirant
A21: 22cfff5c | B21: 45713.523 | C21: 13b5f72f | D21: 86 | E21: Syrah Merlot s/Asp | F21: 25000 | G21: 105 | H21: 1749cd27 | I21: Malbec Prensa | J21: 5000 | K21: 30000 | L21: a43178d5 | M21: Syrah Merlot s/Asp gota | N21: Descube Gota
A22: 1ee5f0af | B22: 45713.537 | C22: 13b5f72f | D22: 86 | E22: Syrah Merlot s/Asp | F22: 7500 | G22: 108 | J22: 0 | K22: 7500 | L22: a1ad6cb4 | M22: Syrah Merlot s/Asp Gota
A23: 9eab323a | B23: 45713.541 | C23: 977cb5a1 | D23: 92 | E23: Syrah Tempranillo | F23: 39700 | G23: 86 | H23: 13b5f72f | I23: Syrah Merlot s/Asp | J23: 7500 | K23: 47200 | L23: 3b2a1e70 | M23: Syrah Tempranillo s/Asp 2da | N23: Gota y Prensa sobre orujos Aspiran 2da pasada
A24: 57f7f4a6 | B24: 45713.71 | C24: cff5f914 | D24: 60 | E24: Prueva 2 Variedad | F24: 8000 | G24: 59 | H24: 00e2c403 | I24: prueba 1 | J24: 10000 | K24: 18000 | L24: fa54e834 | M24: Prueva 2 Variedad
A25: 96b203c8 | B25: 45713.713 | C25: cff5f914 | D25: 60 | E25: Prueva 2 Variedad | F25: 7000 | G25: 59 | H25: fa54e834 | I25: Prueva 2 Variedad | J25: 18000 | K25: 25000 | L25: 24faf549 | M25: Prueva 2 Variedad
A26: a78ab6e7 | B26: 45713.722 | C26: cff5f914 | D26: 60 | E26: Prueva 2 Variedad | F26: 10000 | G26: 59 | H26: 24faf549 | I26: Prueva 2 Variedad | J26: 25000 | K26: 35000 | L26: 57a0fadf | M26: Prueva 2 Variedad
A27: b92404cd | B27: 45713.723 | C27: cff5f914 | D27: 60 | E27: Prueva 2 Variedad | F27: 10000 | G27: 59 | H27: 57a0fadf | I27: Prueva 2 Variedad | J27: 35000 | K27: 45000 | L27: c980cfc2 | M27: Prueva 2 Variedad
A28: ee34047e | B28: 45713.738 | C28: 57a0fadf | D28: 59 | E28: Prueva 2 Variedad | F28: 5000 | G28: 60 | H28: cff5f914 | I28: Prueva 2 Variedad | J28: 20000 | K28: 25000 | L28: e2c70b60 | M28: Prueva 2 Variedad
A29: fe7eff9f | B29: 45713.739 | C29: 57a0fadf | D29: 59 | E29: Prueva 2 Variedad | F29: 3000 | G29: 60 | H29: e2c70b60 | I29: Prueva 2 Variedad | J29: 25000 | K29: 28000 | L29: 5e86e265 | M29: Prueva 2 Variedad
A30: ec72ee89 | B30: 45713.748 | C30: 57a0fadf | D30: 59 | E30: Prueva 2 Variedad | F30: 1500 | G30: 60 | H30: 5e86e265 | I30: Prueva 2 Variedad | J30: 28000 | K30: 29500 | L30: c1d665de | M30: Prueva 2 Variedad
A31: 9e8d0f39 | B31: 45713.773 | C31: b9e5067b | D31: 15 | E31: Cabernet Sauvignon 24 Rect | F31: 20000 | G31: 400 | I31: Vino Re | J31: 0 | K31: 20000 | L31: eeeff983 | M31: Cabernet Sauvignon 24 Rect | N31: Vino rectificado utilizado
A32: 7b4bffff | B32: 45713.779 | C32: 26b37af9 | D32: 52 | E32: Chardonnay 24 Rect | F32: 10000 | G32: 400 | H32: eeeff983 | I32: Cabernet Sauvignon 24 Rect | J32: 20000 | K32: 30000 | L32: ae4bc1ac | M32: Chardonnay 24 Rect | N32: Rectificado utilizado
A33: 490375eb | B33: 45713.794 | C33: d6272af5 | D33: 80 | E33: Merlot s/ Asp | F33: 15000 | G33: 103 | H33: 903e1ab8 | I33: Aspirant | J33: 15000 | K33: 30000 | L33: a22cb4a2 | M33: Merlot s/ Asp
A34: e1980736 | B34: 45713.797 | C34: a43178d5 | D34: 105 | E34: Syrah Merlot s/Asp gota | F34: 16000 | G34: 400 | H34: ae4bc1ac | I34: Chardonnay 24 Rect | J34: 30000 | K34: 46000 | L34: 0b7fd98e | M34: Syrah Merlot s/Asp gota | N34: Ajuste Volumen
A35: 2d753a75 | B35: 45713.798 | C35: 3c569c0a | D35: 84 | E35: Merlot s/Asp | F35: 16000 | G35: 105 | H35: a43178d5 | I35: Syrah Merlot s/Asp gota | J35: 14000 | K35: 30000 | L35: 7ad5b1b2 | M35: Malbec con Merlot s/Asp
A36: da96250f | B36: 45713.799 | C36: 3c569c0a | D36: 84 | E36: Merlot s/Asp | F36: 11000 | G36: 106 | J36: 0 | K36: 11000 | L36: 00bdd4ad | M36: Merlot s/Asp
A37: c98d4615 | B37: 45714.411 | C37: e3903041 | D37: 89 | E37: Syrah Colombo | F37: 36000 | G37: 84 | H37: 3c569c0a | I37: Merlot s/Asp | J37: 3000 | K37: 39000 | L37: 7082548e | M37: Syrah Colom s/Asp 2 | N37: Gota y Prensa sobre Aspiran 2da pasada
A38: 277c1553 | B38: 45715.409 | C38: d6272af5 | D38: 80 | E38: Merlot s/ Asp | F38: 4000 | G38: 109 | J38: 0 | K38: 4000 | L38: 9776a719 | M38: Merlot s/ Asp descube
A39: 150bb873 | B39: 45715.41 | C39: f8624f14 | D39: 85 | E39: Merlot s/Asp | F39: 20000 | G39: 109 | H39: 9776a719 | I39: Merlot s/ Asp descube | J39: 4000 | K39: 24000 | L39: d6ff9a07 | M39: Merlot s/Asp descube
A40: 828ab6d5 | B40: 45715.411 | C40: f8624f14 | D40: 85 | E40: Merlot s/Asp | F40: 3000 | G40: 110 | J40: 0 | K40: 3000 | L40: 8c09a554 | M40: Merlot s/Asp descube | N40: Gota
A41: 7463f544 | B41: 45715.412 | C41: d177809a | D41: 83 | E41: Syrah | F41: 10000 | G41: 80 | H41: d6272af5 | I41: Merlot s/ Asp | J41: 3000 | K41: 13000 | L41: 7525cd32 | M41: Syrah s/Asp 2da | N41: Gota
...

Sheet SQL_GENERADO_V3
A1: -- ========================================
A2: -- SCRIPT SQL GENERADO AUTOMÁTICAMENTE
A3: -- Bodega - Sistema de Gestión de Piletas
A4: -- ========================================
A6: -- 1. TABLA: Estado_pileta
A7: INSERT INTO Estado_pileta (nombre) VALUES ('ACTIVO');
A9: -- 2. TABLA: Tipo_movimiento
A10: INSERT INTO Tipo_movimiento (nombre) VALUES ('Trasiego');
A11: INSERT INTO Tipo_movimiento (nombre) VALUES ('Ajuste Volumen');
A12: INSERT INTO Tipo_movimiento (nombre) VALUES ('Llenado');
A14: -- 3. TABLA: Variedad
A15: INSERT INTO Variedad (nombre, descripcion) VALUES ('Syrah', NULL);
... A4365: -- ========================================

Sheet GLOBAL
A1: ID Global | B1: Pileta Llena | C1: Pileta Numero | D1: Lote | E1: Estado
A2: 15343ec1 | C2: 116 | D2: 8347bdfc

Sheet ESTADO_PILETAS
A1: ID Estado Pileta
A2: Fermentando
A3: Descubada
A4: 1er Trasiego
A5: 2do Trasiego
A6: Terminado
A7: Filtrado Tang
A8: Rectificado
A9: Desvinada
A10: Recarga Fermentando
A11: Traslado Venta

Sheet CIU
A1: Fecha | B1: Sem | C1: Rto. | D1: Productor | E1: Finca | F1: I.N.V. | G1: Cambio | H1: Ctel. | I1: Tachos | J1: Chofer | K1: CUIT / CUIL | L1: Camion | M1: Modelo | N1: Patente | O1: Bruto | P1: Tara | Q1: Neto | R1: Uva Real | S1: Variedad CIU | T1: Destino VINO | U1: Brix Real | V1: T. Azuc. | W1: Nº - CIU | X1: Cosecha | Y1: Vasija
A2: =IFERROR(__xludf.DUMMYFUNCTION("IMPORTRANGE(""https://docs.google.com/spreadsheets/d/1K4FbrEqBWgpGHU7endU5yHpLzeM0dREtUGQF3mOWIUk/edit?gid=542800275#gid=542800275"",""CIU_EXPO!A2:Y700"")"),"#REF!") -> #REF!

Sheet PILETASEXPO
A1: ID_PILETA | B1: Capacidad | C1: Lote Pta | D1: Varietal | E1: Volumen
A2: 1 | B2: 107500 | C2: {=PILETAS!C2:C130} | D2: {=XLOOKUP(C2,'PILETAS LOTES'!$A$2:$A1000,'PILETAS LOTES'!$F$2:$F1000,"",0)} | E2: {=XLOOKUP(C2,'PILETAS LOTES'!$A$2:$A1000,'PILETAS LOTES'!$H$2:$H1000,"",0)}
A3: 2 | B3: 8400 | C3: da997936 | D3: {=XLOOKUP(C3,'PILETAS LOTES'!$A$2:$A1000,'PILETAS LOTES'!$F$2:$F1000,"",0)} -> Chardonnay | E3: {=XLOOKUP(C3,'PILETAS LOTES'!$A$2:$A1000,'PILETAS LOTES'!$H$2:$H1000,"",0)} -> 2200
A4: 3 | B4: 15000 | D4: {=XLOOKUP(C4,'PILETAS LOTES'!$A$2:$A1000,'PILETAS LOTES'!$F$2:$F1000,"",0)} | E4: {=XLOOKUP(C4,'PILETAS LOTES'!$A$2:$A1000,'PILETAS LOTES'!$H$2:$H1000,"",0)}
A5: 4 | B5: 26000 | D5: {=XLOOKUP(C5,'PILETAS LOTES'!$A$2:$A1000,'PILETAS LOTES'!$F$2:$F1000,"",0)} | E5: {=XLOOKUP(C5,'PILETAS LOTES'!$A$2:$A1000,'PILETAS LOTES'!$H$2:$H1000,"",0)}
A6: 5 | B6: 30000 | C6: ebf08055 | D6: {=XLOOKUP(C6,'PILETAS LOTES'!$A$2:$A1000,'PILETAS LOTES'!$F$2:$F1000,"",0)} -> Chardonnay | E6: {=XLOOKUP(C6,'PILETAS LOTES'!$A$2:$A1000,'PILETAS LOTES'!$H$2:$H1000,"",0)} -> 30000
A7: 6 | B7: 32000 | C7: a324303d | D7: {=XLOOKUP(C7,'PILETAS LOTES'!$A$2:$A1000,'PILETAS LOTES'!$F$2:$F1000,"",0)} | E7: {=XLOOKUP(C7,'PILETAS LOTES'!$A$2:$A1000,'PILETAS LOTES'!$H$2:$H1000,"",0)}
A8: 7 | B8: 30000 | D8: {=XLOOKUP(C8,'PILETAS LOTES'!$A$2:$A1000,'PILETAS LOTES'!$F$2:$F1000,"",0)} | E8: {=XLOOKUP(C8,'PILETAS LOTES'!$A$2:$A1000,'PILETAS LOTES'!$H$2:$H1000,"",0)}
A9: 8 | B9: 22000 | C9: 376dbee6 | D9: {=XLOOKUP(C9,'PILETAS LOTES'!$A$2:$A1000,'PILETAS LOTES'!$F$2:$F1000,"",0)} -> Chardonnay | E9: {=XLOOKUP(C9,'PILETAS LOTES'!$A$2:$A1000,'PILETAS LOTES'!$H$2:$H1000,"",0)} -> 22000
A10: 9 | B10: 30000 | D10: {=XLOOKUP(C10,'PILETAS LOTES'!$A$2:$A1000,'PILETAS LOTES'!$F$2:$F1000,"",0)} | E10: {=XLOOKUP(C10,'PILETAS LOTES'!$A$2:$A1000,'PILETAS LOTES'!$H$2:$H1000,"",0)}
A11: 10 | B11: 21000 | C11: f9bf68a3 | D11: {=XLOOKUP(C11,'PILETAS LOTES'!$A$2:$A1000,'PILETAS LOTES'!$F$2:$F1000,"",0)} -> Chardonnay | E11: {=XLOOKUP(C11,'PILETAS LOTES'!$A$2:$A1000,'PILETAS LOTES'!$H$2:$H1000,"",0)} -> 21000
A12: 11 | B12: 36000 | D12: {=XLOOKUP(C12,'PILETAS LOTES'!$A$2:$A1000,'PILETAS LOTES'!$F$2:$F1000,"",0)} | E12: {=XLOOKUP(C12,'PILETAS LOTES'!$A$2:$A1000,'PILETAS LOTES'!$H$2:$H1000,"",0)}
A13: 12 | B13: 35300 | D13: {=XLOOKUP(C13,'PILETAS LOTES'!$A$2:$A1000,'PILETAS LOTES'!$F$2:$F1000,"",0)} | E13: {=XLOOKUP(C13,'PILETAS LOTES'!$A$2:$A1000,'PILETAS LOTES'!$H$2:$H1000,"",0)}
A14: 13 | B14: 20000 | D14: {=XLOOKUP(C14,'PILETAS LOTES'!$A$2:$A1000,'PILETAS LOTES'!$F$2:$F1000,"",0)} | E14: {=XLOOKUP(C14,'PILETAS LOTES'!$A$2:$A1000,'PILETAS LOTES'!$H$2:$H1000,"",0)}
A15: 14 | B15: 37000 | C15: 10b87434 | D15: {=XLOOKUP(C15,'PILETAS LOTES'!$A$2:$A1000,'PILETAS LOTES'!$F$2:$F1000,"",0)} -> Aspirant | E15: {=XLOOKUP(C15,'PILETAS LOTES'!$A$2:$A1000,'PILETAS LOTES'!$H$2:$H1000,"",0)} -> 37000
A16: 15 | B16: 36500 | D16: {=XLOOKUP(C16,'PILETAS LOTES'!$A$2:$A1000,'PILETAS LOTES'!$F$2:$F1000,"",0)} | E16: {=XLOOKUP(C16,'PILETAS LOTES'!$A$2:$A1000,'PILETAS LOTES'!$H$2:$H1000,"",0)}
A17: 16 | B17: 19500 | C17: 869e8a1b | D17: {=XLOOKUP(C17,'PILETAS LOTES'!$A$2:$A1000,'PILETAS LOTES'!$F$2:$F1000,"",0)} | E17: {=XLOOKUP(C17,'PILETAS LOTES'!$A$2:$A1000,'PILETAS LOTES'!$H$2:$H1000,"",0)}
A18: 17 | B18: 39500 | D18: {=XLOOKUP(C18,'PILETAS LOTES'!$A$2:$A1000,'PILETAS LOTES'!$F$2:$F1000,"",0)} | E18: {=XLOOKUP(C18,'PILETAS LOTES'!$A$2:$A1000,'PILETAS LOTES'!$H$2:$H1000,"",0)}
A19: 18 | B19: 39500 | D19: {=XLOOKUP(C19,'PILETAS LOTES'!$A$2:$A1000,'PILETAS LOTES'!$F$2:$F1000,"",0)} | E19: {=XLOOKUP(C19,'PILETAS LOTES'!$A$2:$A1000,'PILETAS LOTES'!$H$2:$H1000,"",0)}
A20: 19 | B20: 27500 | D20: {=XLOOKUP(C20,'PILETAS LOTES'!$A$2:$A1000,'PILETAS LOTES'!$F$2:$F1000,"",0)} | E20: {=XLOOKUP(C20,'PILETAS LOTES'!$A$2:$A1000,'PILETAS LOTES'!$H$2:$H1000,"",0)}
A21: 20 | B21: 38100 | D21: {=XLOOKUP(C21,'PILETAS LOTES'!$A$2:$A1000,'PILETAS LOTES'!$F$2:$F1000,"",0)} | E21: {=XLOOKUP(C21,'PILETAS LOTES'!$A$2:$A1000,'PILETAS LOTES'!$H$2:$H1000,"",0)}
A22: 21 | B22: 28000 | D22: {=XLOOKUP(C22,'PILETAS LOTES'!$A$2:$A1000,'PILETAS LOTES'!$F$2:$F1000,"",0)} | E22: {=XLOOKUP(C22,'PILETAS LOTES'!$A$2:$A1000,'PILETAS LOTES'!$H$2:$H1000,"",0)}
A23: 22 | B23: 41100 | D23: {=XLOOKUP(C23,'PILETAS LOTES'!$A$2:$A1000,'PILETAS LOTES'!$F$2:$F1000,"",0)} | E23: {=XLOOKUP(C23,'PILETAS LOTES'!$A$2:$A1000,'PILETAS LOTES'!$H$2:$H1000,"",0)}
A24: 23 | B24: 197100 | D24: {=XLOOKUP(C24,'PILETAS LOTES'!$A$2:$A1000,'PILETAS LOTES'!$F$2:$F1000,"",0)} | E24: {=XLOOKUP(C24,'PILETAS LOTES'!$A$2:$A1000,'PILETAS LOTES'!$H$2:$H1000,"",0)}
A25: 24 | B25: 186600 | C25: b3a40361 | D25: {=XLOOKUP(C25,'PILETAS LOTES'!$A$2:$A1000,'PILETAS LOTES'!$F$2:$F1000,"",0)} -> Malbec | E25: {=XLOOKUP(C25,'PILETAS LOTES'!$A$2:$A1000,'PILETAS LOTES'!$H$2:$H1000,"",0)} -> 186600
A26: 25 | B26: 194300 | C26: a2728d01 | D26: {=XLOOKUP(C26,'PILETAS LOTES'!$A$2:$A1000,'PILETAS LOTES'!$F$2:$F1000,"",0)} | E26: {=XLOOKUP(C26,'PILETAS LOTES'!$A$2:$A1000,'PILETAS LOTES'!$H$2:$H1000,"",0)}
A27: 26 | B27: 207600 | C27: a37dae6b | D27: {=XLOOKUP(C27,'PILETAS LOTES'!$A$2:$A1000,'PILETAS LOTES'!$F$2:$F1000,"",0)} -> Tinto | E27: {=XLOOKUP(C27,'PILETAS LOTES'!$A$2:$A1000,'PILETAS LOTES'!$H$2:$H1000,"",0)} -> 207600
A28: 27 | B28: 207100 | D28: {=XLOOKUP(C28,'PILETAS LOTES'!$A$2:$A1000,'PILETAS LOTES'!$F$2:$F1000,"",0)} | E28: {=XLOOKUP(C28,'PILETAS LOTES'!$A$2:$A1000,'PILETAS LOTES'!$H$2:$H1000,"",0)}
A29: 28 | B29: 216000 | D29: {=XLOOKUP(C29,'PILETAS LOTES'!$A$2:$A1000,'PILETAS LOTES'!$F$2:$F1000,"",0)} | E29: {=XLOOKUP(C29,'PILETAS LOTES'!$A$2:$A1000,'PILETAS LOTES'!$H$2:$H1000,"",0)}
A30: 29 | B30: 20400 | D30: {=XLOOKUP(C30,'PILETAS LOTES'!$A$2:$A1000,'PILETAS LOTES'!$F$2:$F1000,"",0)} | E30: {=XLOOKUP(C30,'PILETAS LOTES'!$A$2:$A1000,'PILETAS LOTES'!$H$2:$H1000,"",0)}
A31: 30 | B31: 38800 | D31: {=XLOOKUP(C31,'PILETAS LOTES'!$A$2:$A1000,'PILETAS LOTES'!$F$2:$F1000,"",0)} | E31: {=XLOOKUP(C31,'PILETAS LOTES'!$A$2:$A1000,'PILETAS LOTES'!$H$2:$H1000,"",0)}
A32: 31 | B32: 25700 | D32: {=XLOOKUP(C32,'PILETAS LOTES'!$A$2:$A1000,'PILETAS LOTES'!$F$2:$F1000,"",0)} | E32: {=XLOOKUP(C32,'PILETAS LOTES'!$A$2:$A1000,'PILETAS LOTES'!$H$2:$H1000,"",0)}
A33: 32 | B33: 36300 | D33: {=XLOOKUP(C33,'PILETAS LOTES'!$A$2:$A1000,'PILETAS LOTES'!$F$2:$F1000,"",0)} | E33: {=XLOOKUP(C33,'PILETAS LOTES'!$A$2:$A1000,'PILETAS LOTES'!$H$2:$H1000,"",0)}
A34: 33 | B34: 25300 | C34: 7def2139 | D34: {=XLOOKUP(C34,'PILETAS LOTES'!$A$2:$A1000,'PILETAS LOTES'!$F$2:$F1000,"",0)} -> Chardonnay | E34: {=XLOOKUP(C34,'PILETAS LOTES'!$A$2:$A1000,'PILETAS LOTES'!$H$2:$H1000,"",0)} -> 25300
A35: 34 | B35: 39500 | C35: 08cd1438 | D35: {=XLOOKUP(C35,'PILETAS LOTES'!$A$2:$A1000,'PILETAS LOTES'!$F$2:$F1000,"",0)} -> Malbec | E35: {=XLOOKUP(C35,'PILETAS LOTES'!$A$2:$A1000,'PILETAS LOTES'!$H$2:$H1000,"",0)} -> 39500
A36: 35 | B36: 39300 | D36: {=XLOOKUP(C36,'PILETAS LOTES'!$A$2:$A1000,'PILETAS LOTES'!$F$2:$F1000,"",0)} | E36: {=XLOOKUP(C36,'PILETAS LOTES'!$A$2:$A1000,'PILETAS LOTES'!$H$2:$H1000,"",0)}
A37: 36 | B37: 19700 | C37: 0997a77d | D37: {=XLOOKUP(C37,'PILETAS LOTES'!$A$2:$A1000,'PILETAS LOTES'!$F$2:$F1000,"",0)} -> Torrontes | E37: {=XLOOKUP(C37,'PILETAS LOTES'!$A$2:$A1000,'PILETAS LOTES'!$H$2:$H1000,"",0)} -> 19700
A38: 37 | B38: 39000 | D38: {=XLOOKUP(C38,'PILETAS LOTES'!$A$2:$A1000,'PILETAS LOTES'!$F$2:$F1000,"",0)} | E38: {=XLOOKUP(C38,'PILETAS LOTES'!$A$2:$A1000,'PILETAS LOTES'!$H$2:$H1000,"",0)}
A39: 38 | B39: 23500 | D39: {=XLOOKUP(C39,'PILETAS LOTES'!$A$2:$A1000,'PILETAS LOTES'!$F$2:$F1000,"",0)} | E39: {=XLOOKUP(C39,'PILETAS LOTES'!$A$2:$A1000,'PILETAS LOTES'!$H$2:$H1000,"",0)}
A40: 39 | B40: 40000 | D40: {=XLOOKUP(C40,'PILETAS LOTES'!$A$2:$A1000,'PILETAS LOTES'!$F$2:$F1000,"",0)} | E40: {=XLOOKUP(C40,'PILETAS LOTES'!$A$2:$A1000,'PILETAS LOTES'!$H$2:$H1000,"",0)}
...

Sheet ANALISIS_EXPO
A1: ID_Analaisis | B1: Fecha | C1: Pileta | D1: Lote | E1: Capac | F1: Tipo | G1: Alcohol | H1: Azucar | I1: Volatil | J1: Ac. Total | K1: Ph | L1: Anhi. Libre | M1: Anhi. Total | N1: extracto seco | O1: 420 | P1: 520 | Q1: 620 | R1: Intensidad | S1: Indice | T1: Suma 420_520_620 | U1: Brix | V1: oxigeno | W1: Observaciones
A2: =IFERROR(__xludf.DUMMYFUNCTION("IMPORTRANGE(""https://docs.google.com/spreadsheets/d/1TzUfNWs0yocwDUIiqYtAe6nRr0RJptqO5h0qGqW4PVk/edit?gid=1088908225#gid=1088908225"",""BD_ANALISIS_EXPO!a2:W"")"),2.0) -> 2 | B2: =IFERROR(__xludf.DUMMYFUNCTION("""COMPUTED_VALUE"""),45308.0) -> 45308 | C2: =IFERROR(__xludf.DUMMYFUNCTION("""COMPUTED_VALUE"""),54.0) -> 54 | D2: =IFERROR(__xludf.DUMMYFUNCTION("""COMPUTED_VALUE"""),"#REF!") -> #REF! | E2: =IFERROR(__xludf.DUMMYFUNCTION("""COMPUTED_VALUE"""),22900.0) -> 22900 | F2: =IFERROR(__xludf.DUMMYFUNCTION("""COMPUTED_VALUE"""),"Malbec rectificado") -> Malbec rectificado | G2: =IFERROR(__xludf.DUMMYFUNCTION("""COMPUTED_VALUE"""),13.0) -> 13 | H2: =IFERROR(__xludf.DUMMYFUNCTION("""COMPUTED_VALUE"""),2.0) -> 2 | I2: =IFERROR(__xludf.DUMMYFUNCTION("""COMPUTED_VALUE"""),0.55) -> 0.55 | J2: =IFERROR(__xludf.DUMMYFUNCTION("""COMPUTED_VALUE"""),6.9) -> 6.9 | K2: =IFERROR(__xludf.DUMMYFUNCTION("""COMPUTED_VALUE"""),2.11) -> 2.11 | L2: =IFERROR(__xludf.DUMMYFUNCTION("""COMPUTED_VALUE"""),25.0) -> 25 | M2: =IFERROR(__xludf.DUMMYFUNCTION("""COMPUTED_VALUE"""),90.0) -> 90
A3: =IFERROR(__xludf.DUMMYFUNCTION("""COMPUTED_VALUE"""),3.0) -> 3 | B3: =IFERROR(__xludf.DUMMYFUNCTION("""COMPUTED_VALUE"""),45308.0) -> 45308 | C3: =IFERROR(__xludf.DUMMYFUNCTION("""COMPUTED_VALUE"""),15.0) -> 15 | E3: =IFERROR(__xludf.DUMMYFUNCTION("""COMPUTED_VALUE"""),36500.0) -> 36500 | F3: =IFERROR(__xludf.DUMMYFUNCTION("""COMPUTED_VALUE"""),"Malbec rectificado") -> Malbec rectificado | G3: =IFERROR(__xludf.DUMMYFUNCTION("""COMPUTED_VALUE"""),12.9) -> 12.9 | H3: =IFERROR(__xludf.DUMMYFUNCTION("""COMPUTED_VALUE"""),2.0) -> 2 | I3: =IFERROR(__xludf.DUMMYFUNCTION("""COMPUTED_VALUE"""),0.57) -> 0.57 | J3: =IFERROR(__xludf.DUMMYFUNCTION("""COMPUTED_VALUE"""),8.26) -> 8.26 | K3: =IFERROR(__xludf.DUMMYFUNCTION("""COMPUTED_VALUE"""),2.16) -> 2.16 | L3: =IFERROR(__xludf.DUMMYFUNCTION("""COMPUTED_VALUE"""),26.0) -> 26 | M3: =IFERROR(__xludf.DUMMYFUNCTION("""COMPUTED_VALUE"""),75.0) -> 75
A4: =IFERROR(__xludf.DUMMYFUNCTION("""COMPUTED_VALUE"""),4.0) -> 4 | B4: =IFERROR(__xludf.DUMMYFUNCTION("""COMPUTED_VALUE"""),45308.0) -> 45308 | C4: =IFERROR(__xludf.DUMMYFUNCTION("""COMPUTED_VALUE"""),11.0) -> 11 | D4: =IFERROR(__xludf.DUMMYFUNCTION("""COMPUTED_VALUE"""),"#REF!") -> #REF! | E4: =IFERROR(__xludf.DUMMYFUNCTION("""COMPUTED_VALUE"""),36000.0) -> 36000 | F4: =IFERROR(__xludf.DUMMYFUNCTION("""COMPUTED_VALUE"""),"blanco rectificado") -> blanco rectificado | G4: =IFERROR(__xludf.DUMMYFUNCTION("""COMPUTED_VALUE"""),10.0) -> 10 | H4: =IFERROR(__xludf.DUMMYFUNCTION("""COMPUTED_VALUE"""),2.0) -> 2 | I4: =IFERROR(__xludf.DUMMYFUNCTION("""COMPUTED_VALUE"""),0.55) -> 0.55 | J4: =IFERROR(__xludf.DUMMYFUNCTION("""COMPUTED_VALUE"""),6.12) -> 6.12 | K4: =IFERROR(__xludf.DUMMYFUNCTION("""COMPUTED_VALUE"""),2.2) -> 2.2 | L4: =IFERROR(__xludf.DUMMYFUNCTION("""COMPUTED_VALUE"""),25.0) -> 25 | M4: =IFERROR(__xludf.DUMMYFUNCTION("""COMPUTED_VALUE"""),90.0) -> 90
A5: =IFERROR(__xludf.DUMMYFUNCTION("""COMPUTED_VALUE"""),5.0) -> 5 | B5: =IFERROR(__xludf.DUMMYFUNCTION("""COMPUTED_VALUE"""),45308.0) -> 45308 | C5: =IFERROR(__xludf.DUMMYFUNCTION("""COMPUTED_VALUE"""),36.0) -> 36 | D5: =IFERROR(__xludf.DUMMYFUNCTION("""COMPUTED_VALUE"""),"1.020") -> 1.020 | E5: =IFERROR(__xludf.DUMMYFUNCTION("""COMPUTED_VALUE"""),19700.0) -> 19700 | F5: =IFERROR(__xludf.DUMMYFUNCTION("""COMPUTED_VALUE"""),"Criolla Rectificada") -> Criolla Rectificada | G5: =IFERROR(__xludf.DUMMYFUNCTION("""COMPUTED_VALUE"""),13.0) -> 13 | H5: =IFERROR(__xludf.DUMMYFUNCTION("""COMPUTED_VALUE"""),2.0) -> 2 | I5: =IFERROR(__xludf.DUMMYFUNCTION("""COMPUTED_VALUE"""),0.6) -> 0.6 | J5: =IFERROR(__xludf.DUMMYFUNCTION("""COMPUTED_VALUE"""),6.2) -> 6.2 | K5: =IFERROR(__xludf.DUMMYFUNCTION("""COMPUTED_VALUE"""),2.11) -> 2.11 | L5: =IFERROR(__xludf.DUMMYFUNCTION("""COMPUTED_VALUE"""),22.0) -> 22 | M5: =IFERROR(__xludf.DUMMYFUNCTION("""COMPUTED_VALUE"""),110.0) -> 110
A6: =IFERROR(__xludf.DUMMYFUNCTION("""COMPUTED_VALUE"""),6.0) -> 6 | B6: =IFERROR(__xludf.DUMMYFUNCTION("""COMPUTED_VALUE"""),45309.0) -> 45309 | C6: =IFERROR(__xludf.DUMMYFUNCTION("""COMPUTED_VALUE"""),16.0) -> 16 | E6: =IFERROR(__xludf.DUMMYFUNCTION("""COMPUTED_VALUE"""),19500.0) -> 19500 | F6: =IFERROR(__xludf.DUMMYFUNCTION("""COMPUTED_VALUE"""),"rosado rectificado") -> rosado rectificado | G6: =IFERROR(__xludf.DUMMYFUNCTION("""COMPUTED_VALUE"""),12.9) -> 12.9 | H6: =IFERROR(__xludf.DUMMYFUNCTION("""COMPUTED_VALUE"""),2.0) -> 2 | I6: =IFERROR(__xludf.DUMMYFUNCTION("""COMPUTED_VALUE"""),0.5) -> 0.5 | J6: =IFERROR(__xludf.DUMMYFUNCTION("""COMPUTED_VALUE"""),6.9) -> 6.9 | K6: =IFERROR(__xludf.DUMMYFUNCTION("""COMPUTED_VALUE"""),2.09) -> 2.09 | L6: =IFERROR(__xludf.DUMMYFUNCTION("""COMPUTED_VALUE"""),19.0) -> 19 | M6: =IFERROR(__xludf.DUMMYFUNCTION("""COMPUTED_VALUE"""),160.0) -> 160
A7: =IFERROR(__xludf.DUMMYFUNCTION("""COMPUTED_VALUE"""),7.0) -> 7 | B7: =IFERROR(__xludf.DUMMYFUNCTION("""COMPUTED_VALUE"""),45309.0) -> 45309 | C7: =IFERROR(__xludf.DUMMYFUNCTION("""COMPUTED_VALUE"""),42.0) -> 42 | D7: =IFERROR(__xludf.DUMMYFUNCTION("""COMPUTED_VALUE"""),"#REF!") -> #REF! | E7: =IFERROR(__xludf.DUMMYFUNCTION("""COMPUTED_VALUE"""),35900.0) -> 35900 | F7: =IFERROR(__xludf.DUMMYFUNCTION("""COMPUTED_VALUE"""),"Cabernet Sauvignon rectificado") -> Cabernet Sauvignon rectificado | G7: =IFERROR(__xludf.DUMMYFUNCTION("""COMPUTED_VALUE"""),13.0) -> 13 | H7: =IFERROR(__xludf.DUMMYFUNCTION("""COMPUTED_VALUE"""),2.0) -> 2 | I7: =IFERROR(__xludf.DUMMYFUNCTION("""COMPUTED_VALUE"""),0.57) -> 0.57 | J7: =IFERROR(__xludf.DUMMYFUNCTION("""COMPUTED_VALUE"""),8.8) -> 8.8 | K7: =IFERROR(__xludf.DUMMYFUNCTION("""COMPUTED_VALUE"""),2.21) -> 2.21 | L7: =IFERROR(__xludf.DUMMYFUNCTION("""COMPUTED_VALUE"""),25.0) -> 25 | M7: =IFERROR(__xludf.DUMMYFUNCTION("""COMPUTED_VALUE"""),100.0) -> 100
A8: =IFERROR(__xludf.DUMMYFUNCTION("""COMPUTED_VALUE"""),8.0) -> 8 | B8: =IFERROR(__xludf.DUMMYFUNCTION("""COMPUTED_VALUE"""),45313.0) -> 45313 | C8: =IFERROR(__xludf.DUMMYFUNCTION("""COMPUTED_VALUE"""),48.0) -> 48 | D8: =IFERROR(__xludf.DUMMYFUNCTION("""COMPUTED_VALUE"""),"#REF!") -> #REF! | E8: =IFERROR(__xludf.DUMMYFUNCTION("""COMPUTED_VALUE"""),26000.0) -> 26000 | F8: =IFERROR(__xludf.DUMMYFUNCTION("""COMPUTED_VALUE"""),"Cabernet Sauvignon rectificado") -> Cabernet Sauvignon rectificado | G8: =IFERROR(__xludf.DUMMYFUNCTION("""COMPUTED_VALUE"""),12.8) -> 12.8 | H8: =IFERROR(__xludf.DUMMYFUNCTION("""COMPUTED_VALUE"""),2.0) -> 2 | I8: =IFERROR(__xludf.DUMMYFUNCTION("""COMPUTED_VALUE"""),0.53) -> 0.53 | J8: =IFERROR(__xludf.DUMMYFUNCTION("""COMPUTED_VALUE"""),8.4) -> 8.4 | K8: =IFERROR(__xludf.DUMMYFUNCTION("""COMPUTED_VALUE"""),2.16) -> 2.16 | L8: =IFERROR(__xludf.DUMMYFUNCTION("""COMPUTED_VALUE"""),25.0) -> 25 | M8: =IFERROR(__xludf.DUMMYFUNCTION("""COMPUTED_VALUE"""),90.0) -> 90
A9: =IFERROR(__xludf.DUMMYFUNCTION("""COMPUTED_VALUE"""),9.0) -> 9 | B9: =IFERROR(__xludf.DUMMYFUNCTION("""COMPUTED_VALUE"""),45314.0) -> 45314 | C9: =IFERROR(__xludf.DUMMYFUNCTION("""COMPUTED_VALUE"""),49.0) -> 49 | D9: =IFERROR(__xludf.DUMMYFUNCTION("""COMPUTED_VALUE"""),"#REF!") -> #REF! | E9: =IFERROR(__xludf.DUMMYFUNCTION("""COMPUTED_VALUE"""),26000.0) -> 26000 | F9: =IFERROR(__xludf.DUMMYFUNCTION("""COMPUTED_VALUE"""),"Cabernet Sauvignon rectificado") -> Cabernet Sauvignon rectificado | G9: =IFERROR(__xludf.DUMMYFUNCTION("""COMPUTED_VALUE"""),12.7) -> 12.7 | H9: =IFERROR(__xludf.DUMMYFUNCTION("""COMPUTED_VALUE"""),2.0) -> 2 | I9: =IFERROR(__xludf.DUMMYFUNCTION("""COMPUTED_VALUE"""),0.57) -> 0.57 | J9: =IFERROR(__xludf.DUMMYFUNCTION("""COMPUTED_VALUE"""),8.3) -> 8.3 | K9: =IFERROR(__xludf.DUMMYFUNCTION("""COMPUTED_VALUE"""),2.18) -> 2.18 | L9: =IFERROR(__xludf.DUMMYFUNCTION("""COMPUTED_VALUE"""),27.0) -> 27 | M9: =IFERROR(__xludf.DUMMYFUNCTION("""COMPUTED_VALUE"""),110.0) -> 110
A10: =IFERROR(__xludf.DUMMYFUNCTION("""COMPUTED_VALUE"""),10.0) -> 10 | C10: =IFERROR(__xludf.DUMMYFUNCTION("""COMPUTED_VALUE"""),41.0) -> 41 | D10: =IFERROR(__xludf.DUMMYFUNCTION("""COMPUTED_VALUE"""),"#REF!") -> #REF! | E10: =IFERROR(__xludf.DUMMYFUNCTION("""COMPUTED_VALUE"""),35100.0) -> 35100 | F10: =IFERROR(__xludf.DUMMYFUNCTION("""COMPUTED_VALUE"""),"Cabernet sauvignon recticado") -> Cabernet sauvignon recticado
A11: =IFERROR(__xludf.DUMMYFUNCTION("""COMPUTED_VALUE"""),11.0) -> 11 | B11: =IFERROR(__xludf.DUMMYFUNCTION("""COMPUTED_VALUE"""),44950.0) -> 44950 | C11: =IFERROR(__xludf.DUMMYFUNCTION("""COMPUTED_VALUE"""),50.0) -> 50 | F11: =IFERROR(__xludf.DUMMYFUNCTION("""COMPUTED_VALUE"""),"Malbec montecepas") -> Malbec montecepas | G11: =IFERROR(__xludf.DUMMYFUNCTION("""COMPUTED_VALUE"""),13.1) -> 13.1 | H11: =IFERROR(__xludf.DUMMYFUNCTION("""COMPUTED_VALUE"""),2.0) -> 2 | I11: =IFERROR(__xludf.DUMMYFUNCTION("""COMPUTED_VALUE"""),0.55) -> 0.55 | J11: =IFERROR(__xludf.DUMMYFUNCTION("""COMPUTED_VALUE"""),5.2) -> 5.2 | K11: =IFERROR(__xludf.DUMMYFUNCTION("""COMPUTED_VALUE"""),3.7) -> 3.7 | L11: =IFERROR(__xludf.DUMMYFUNCTION("""COMPUTED_VALUE"""),40.0) -> 40 | M11: =IFERROR(__xludf.DUMMYFUNCTION("""COMPUTED_VALUE"""),130.0) -> 130
A12: =IFERROR(__xludf.DUMMYFUNCTION("""COMPUTED_VALUE"""),12.0) -> 12 | B12: =IFERROR(__xludf.DUMMYFUNCTION("""COMPUTED_VALUE"""),45321.0) -> 45321 | C12: =IFERROR(__xludf.DUMMYFUNCTION("""COMPUTED_VALUE"""),9.0) -> 9 | I12: =IFERROR(__xludf.DUMMYFUNCTION("""COMPUTED_VALUE"""),0.57) -> 0.57 | K12: =IFERROR(__xludf.DUMMYFUNCTION("""COMPUTED_VALUE"""),3.6) -> 3.6 | L12: =IFERROR(__xludf.DUMMYFUNCTION("""COMPUTED_VALUE"""),38.0) -> 38 | M12: =IFERROR(__xludf.DUMMYFUNCTION("""COMPUTED_VALUE"""),120.0) -> 120
A13: =IFERROR(__xludf.DUMMYFUNCTION("""COMPUTED_VALUE"""),13.0) -> 13 | B13: =IFERROR(__xludf.DUMMYFUNCTION("""COMPUTED_VALUE"""),44950.0) -> 44950 | C13: =IFERROR(__xludf.DUMMYFUNCTION("""COMPUTED_VALUE"""),51.0) -> 51 | D13: =IFERROR(__xludf.DUMMYFUNCTION("""COMPUTED_VALUE"""),"1.021") -> 1.021 | E13: =IFERROR(__xludf.DUMMYFUNCTION("""COMPUTED_VALUE"""),2500.0) -> 2500 | F13: =IFERROR(__xludf.DUMMYFUNCTION("""COMPUTED_VALUE"""),"Syrah Malbec") -> Syrah Malbec | G13: =IFERROR(__xludf.DUMMYFUNCTION("""COMPUTED_VALUE"""),13.0) -> 13 | H13: =IFERROR(__xludf.DUMMYFUNCTION("""COMPUTED_VALUE"""),2.0) -> 2 | I13: =IFERROR(__xludf.DUMMYFUNCTION("""COMPUTED_VALUE"""),0.5) -> 0.5 | J13: =IFERROR(__xludf.DUMMYFUNCTION("""COMPUTED_VALUE"""),5.2) -> 5.2 | K13: =IFERROR(__xludf.DUMMYFUNCTION("""COMPUTED_VALUE"""),3.65) -> 3.65 | L13: =IFERROR(__xludf.DUMMYFUNCTION("""COMPUTED_VALUE"""),40.0) -> 40 | M13: =IFERROR(__xludf.DUMMYFUNCTION("""COMPUTED_VALUE"""),100.0) -> 100
A14: =IFERROR(__xludf.DUMMYFUNCTION("""COMPUTED_VALUE"""),14.0) -> 14 | B14: =IFERROR(__xludf.DUMMYFUNCTION("""COMPUTED_VALUE"""),45327.0) -> 45327 | C14: =IFERROR(__xludf.DUMMYFUNCTION("""COMPUTED_VALUE"""),32.0) -> 32 | D14: =IFERROR(__xludf.DUMMYFUNCTION("""COMPUTED_VALUE"""),"#REF!") -> #REF! | E14: =IFERROR(__xludf.DUMMYFUNCTION("""COMPUTED_VALUE"""),36300.0) -> 36300 | F14: =IFERROR(__xludf.DUMMYFUNCTION("""COMPUTED_VALUE"""),"Merlot-syrah 2023") -> Merlot-syrah 2023 | G14: =IFERROR(__xludf.DUMMYFUNCTION("""COMPUTED_VALUE"""),13.2) -> 13.2 | H14: =IFERROR(__xludf.DUMMYFUNCTION("""COMPUTED_VALUE"""),2.0) -> 2 | I14: =IFERROR(__xludf.DUMMYFUNCTION("""COMPUTED_VALUE"""),0.5) -> 0.5 | J14: =IFERROR(__xludf.DUMMYFUNCTION("""COMPUTED_VALUE"""),5.25) -> 5.25 | K14: =IFERROR(__xludf.DUMMYFUNCTION("""COMPUTED_VALUE"""),3.8) -> 3.8 | L14: =IFERROR(__xludf.DUMMYFUNCTION("""COMPUTED_VALUE"""),45.0) -> 45 | M14: =IFERROR(__xludf.DUMMYFUNCTION("""COMPUTED_VALUE"""),130.0) -> 130
A15: =IFERROR(__xludf.DUMMYFUNCTION("""COMPUTED_VALUE"""),15.0) -> 15 | B15: =IFERROR(__xludf.DUMMYFUNCTION("""COMPUTED_VALUE"""),45327.0) -> 45327 | C15: =IFERROR(__xludf.DUMMYFUNCTION("""COMPUTED_VALUE"""),65.0) -> 65 | D15: =IFERROR(__xludf.DUMMYFUNCTION("""COMPUTED_VALUE"""),"#REF!") -> #REF! | E15: =IFERROR(__xludf.DUMMYFUNCTION("""COMPUTED_VALUE"""),17000.0) -> 17000 | F15: =IFERROR(__xludf.DUMMYFUNCTION("""COMPUTED_VALUE"""),"chardonnay-Sauvignon blanc -24") -> chardonnay-Sauvignon blanc -24 | H15: =IFERROR(__xludf.DUMMYFUNCTION("""COMPUTED_VALUE"""),214.0) -> 214 | K15: =IFERROR(__xludf.DUMMYFUNCTION("""COMPUTED_VALUE"""),3.6) -> 3.6
A16: =IFERROR(__xludf.DUMMYFUNCTION("""COMPUTED_VALUE"""),16.0) -> 16 | B16: =IFERROR(__xludf.DUMMYFUNCTION("""COMPUTED_VALUE"""),45327.0) -> 45327 | C16: =IFERROR(__xludf.DUMMYFUNCTION("""COMPUTED_VALUE"""),82.0) -> 82 | D16: =IFERROR(__xludf.DUMMYFUNCTION("""COMPUTED_VALUE"""),"#REF!") -> #REF! | E16: =IFERROR(__xludf.DUMMYFUNCTION("""COMPUTED_VALUE"""),40000.0) -> 40000 | F16: =IFERROR(__xludf.DUMMYFUNCTION("""COMPUTED_VALUE"""),"chardonnay-Sauvignon blanc -24") -> chardonnay-Sauvignon blanc -24 | K16: =IFERROR(__xludf.DUMMYFUNCTION("""COMPUTED_VALUE"""),3.32) -> 3.32
A17: =IFERROR(__xludf.DUMMYFUNCTION("""COMPUTED_VALUE"""),17.0) -> 17 | B17: =IFERROR(__xludf.DUMMYFUNCTION("""COMPUTED_VALUE"""),45327.0) -> 45327 | C17: =IFERROR(__xludf.DUMMYFUNCTION("""COMPUTED_VALUE"""),81.0) -> 81 | D17: =IFERROR(__xludf.DUMMYFUNCTION("""COMPUTED_VALUE"""),"#REF!") -> #REF! | E17: =IFERROR(__xludf.DUMMYFUNCTION("""COMPUTED_VALUE"""),25000.0) -> 25000 | F17: =IFERROR(__xludf.DUMMYFUNCTION("""COMPUTED_VALUE"""),"chardonnay-Sauvignon blanc -24") -> chardonnay-Sauvignon blanc -24 | K17: =IFERROR(__xludf.DUMMYFUNCTION("""COMPUTED_VALUE"""),3.33) -> 3.33
A18: =IFERROR(__xludf.DUMMYFUNCTION("""COMPUTED_VALUE"""),18.0) -> 18 | B18: =IFERROR(__xludf.DUMMYFUNCTION("""COMPUTED_VALUE"""),45328.0) -> 45328 | C18: =IFERROR(__xludf.DUMMYFUNCTION("""COMPUTED_VALUE"""),65.0) -> 65 | D18: =IFERROR(__xludf.DUMMYFUNCTION("""COMPUTED_VALUE"""),"#REF!") -> #REF! | F18: =IFERROR(__xludf.DUMMYFUNCTION("""COMPUTED_VALUE"""),"chardonnay") -> chardonnay | H18: =IFERROR(__xludf.DUMMYFUNCTION("""COMPUTED_VALUE"""),208.0) -> 208 | K18: =IFERROR(__xludf.DUMMYFUNCTION("""COMPUTED_VALUE"""),3.6) -> 3.6
A19: =IFERROR(__xludf.DUMMYFUNCTION("""COMPUTED_VALUE"""),19.0) -> 19 | B19: =IFERROR(__xludf.DUMMYFUNCTION("""COMPUTED_VALUE"""),45329.0) -> 45329 | C19: =IFERROR(__xludf.DUMMYFUNCTION("""COMPUTED_VALUE"""),82.0) -> 82 | D19: =IFERROR(__xludf.DUMMYFUNCTION("""COMPUTED_VALUE"""),"#REF!") -> #REF! | F19: =IFERROR(__xludf.DUMMYFUNCTION("""COMPUTED_VALUE"""),"Chardonnay") -> Chardonnay | H19: =IFERROR(__xludf.DUMMYFUNCTION("""COMPUTED_VALUE"""),6.0) -> 6 | J19: =IFERROR(__xludf.DUMMYFUNCTION("""COMPUTED_VALUE"""),7.3) -> 7.3 | K19: =IFERROR(__xludf.DUMMYFUNCTION("""COMPUTED_VALUE"""),3.3) -> 3.3
A20: =IFERROR(__xludf.DUMMYFUNCTION("""COMPUTED_VALUE"""),20.0) -> 20 | B20: =IFERROR(__xludf.DUMMYFUNCTION("""COMPUTED_VALUE"""),45330.0) -> 45330 | C20: =IFERROR(__xludf.DUMMYFUNCTION("""COMPUTED_VALUE"""),82.0) -> 82 | D20: =IFERROR(__xludf.DUMMYFUNCTION("""COMPUTED_VALUE"""),"#REF!") -> #REF! | F20: =IFERROR(__xludf.DUMMYFUNCTION("""COMPUTED_VALUE"""),"Chardonnay") -> Chardonnay | G20: =IFERROR(__xludf.DUMMYFUNCTION("""COMPUTED_VALUE"""),11.9) -> 11.9 | H20: =IFERROR(__xludf.DUMMYFUNCTION("""COMPUTED_VALUE"""),2.0) -> 2 | I20: =IFERROR(__xludf.DUMMYFUNCTION("""COMPUTED_VALUE"""),0.28) -> 0.28 | J20: =IFERROR(__xludf.DUMMYFUNCTION("""COMPUTED_VALUE"""),7.3) -> 7.3 | K20: =IFERROR(__xludf.DUMMYFUNCTION("""COMPUTED_VALUE"""),3.26) -> 3.26 | L20: =IFERROR(__xludf.DUMMYFUNCTION("""COMPUTED_VALUE"""),25.0) -> 25 | M20: =IFERROR(__xludf.DUMMYFUNCTION("""COMPUTED_VALUE"""),80.0) -> 80
A21: =IFERROR(__xludf.DUMMYFUNCTION("""COMPUTED_VALUE"""),21.0) -> 21 | B21: =IFERROR(__xludf.DUMMYFUNCTION("""COMPUTED_VALUE"""),45330.0) -> 45330 | C21: =IFERROR(__xludf.DUMMYFUNCTION("""COMPUTED_VALUE"""),81.0) -> 81 | D21: =IFERROR(__xludf.DUMMYFUNCTION("""COMPUTED_VALUE"""),"#REF!") -> #REF! | F21: =IFERROR(__xludf.DUMMYFUNCTION("""COMPUTED_VALUE"""),"Chardonnay") -> Chardonnay | G21: =IFERROR(__xludf.DUMMYFUNCTION("""COMPUTED_VALUE"""),12.0) -> 12 | H21: =IFERROR(__xludf.DUMMYFUNCTION("""COMPUTED_VALUE"""),8.0) -> 8 | I21: =IFERROR(__xludf.DUMMYFUNCTION("""COMPUTED_VALUE"""),0.3) -> 0.3 | J21: =IFERROR(__xludf.DUMMYFUNCTION("""COMPUTED_VALUE"""),7.5) -> 7.5 | K21: =IFERROR(__xludf.DUMMYFUNCTION("""COMPUTED_VALUE"""),3.25) -> 3.25 | L21: =IFERROR(__xludf.DUMMYFUNCTION("""COMPUTED_VALUE"""),13.0) -> 13 | M21: =IFERROR(__xludf.DUMMYFUNCTION("""COMPUTED_VALUE"""),76.0) -> 76
A22: =IFERROR(__xludf.DUMMYFUNCTION("""COMPUTED_VALUE"""),22.0) -> 22 | B22: =IFERROR(__xludf.DUMMYFUNCTION("""COMPUTED_VALUE"""),45334.0) -> 45334 | C22: =IFERROR(__xludf.DUMMYFUNCTION("""COMPUTED_VALUE"""),82.0) -> 82 | D22: =IFERROR(__xludf.DUMMYFUNCTION("""COMPUTED_VALUE"""),"#REF!") -> #REF! | F22: =IFERROR(__xludf.DUMMYFUNCTION("""COMPUTED_VALUE"""),"chardonay") -> chardonay | J22: =IFERROR(__xludf.DUMMYFUNCTION("""COMPUTED_VALUE"""),6.5) -> 6.5 | K22: =IFERROR(__xludf.DUMMYFUNCTION("""COMPUTED_VALUE"""),3.5) -> 3.5 | M22: =IFERROR(__xludf.DUMMYFUNCTION("""COMPUTED_VALUE"""),25.0) -> 25
A23: =IFERROR(__xludf.DUMMYFUNCTION("""COMPUTED_VALUE"""),23.0) -> 23 | B23: =IFERROR(__xludf.DUMMYFUNCTION("""COMPUTED_VALUE"""),45334.0) -> 45334 | C23: =IFERROR(__xludf.DUMMYFUNCTION("""COMPUTED_VALUE"""),81.0) -> 81 | D23: =IFERROR(__xludf.DUMMYFUNCTION("""COMPUTED_VALUE"""),"#REF!") -> #REF! | F23: =IFERROR(__xludf.DUMMYFUNCTION("""COMPUTED_VALUE"""),"Chardonnay") -> Chardonnay | G23: =IFERROR(__xludf.DUMMYFUNCTION("""COMPUTED_VALUE"""),12.2) -> 12.2 | H23: =IFERROR(__xludf.DUMMYFUNCTION("""COMPUTED_VALUE"""),2.0) -> 2 | J23: =IFERROR(__xludf.DUMMYFUNCTION("""COMPUTED_VALUE"""),6.2) -> 6.2 | K23: =IFERROR(__xludf.DUMMYFUNCTION("""COMPUTED_VALUE"""),3.55) -> 3.55 | M23: =IFERROR(__xludf.DUMMYFUNCTION("""COMPUTED_VALUE"""),20.0) -> 20
A24: =IFERROR(__xludf.DUMMYFUNCTION("""COMPUTED_VALUE"""),24.0) -> 24 | B24: =IFERROR(__xludf.DUMMYFUNCTION("""COMPUTED_VALUE"""),45335.0) -> 45335 | C24: =IFERROR(__xludf.DUMMYFUNCTION("""COMPUTED_VALUE"""),65.0) -> 65 | D24: =IFERROR(__xludf.DUMMYFUNCTION("""COMPUTED_VALUE"""),"#REF!") -> #REF! | F24: =IFERROR(__xludf.DUMMYFUNCTION("""COMPUTED_VALUE"""),"Chardonnay") -> Chardonnay | G24: =IFERROR(__xludf.DUMMYFUNCTION("""COMPUTED_VALUE"""),12.2) -> 12.2 | H24: =IFERROR(__xludf.DUMMYFUNCTION("""COMPUTED_VALUE"""),2.0) -> 2 | J24: =IFERROR(__xludf.DUMMYFUNCTION("""COMPUTED_VALUE"""),6.5) -> 6.5 | K24: =IFERROR(__xludf.DUMMYFUNCTION("""COMPUTED_VALUE"""),3.6) -> 3.6 | L24: =IFERROR(__xludf.DUMMYFUNCTION("""COMPUTED_VALUE"""),15.0) -> 15
A25: =IFERROR(__xludf.DUMMYFUNCTION("""COMPUTED_VALUE"""),25.0) -> 25 | B25: =IFERROR(__xludf.DUMMYFUNCTION("""COMPUTED_VALUE"""),45335.0) -> 45335 | C25: =IFERROR(__xludf.DUMMYFUNCTION("""COMPUTED_VALUE"""),66.0) -> 66 | D25: =IFERROR(__xludf.DUMMYFUNCTION("""COMPUTED_VALUE"""),"#REF!") -> #REF! | F25: =IFERROR(__xludf.DUMMYFUNCTION("""COMPUTED_VALUE"""),"Chardonnay") -> Chardonnay | G25: =IFERROR(__xludf.DUMMYFUNCTION("""COMPUTED_VALUE"""),12.5) -> 12.5 | H25: =IFERROR(__xludf.DUMMYFUNCTION("""COMPUTED_VALUE"""),2.0) -> 2 | J25: =IFERROR(__xludf.DUMMYFUNCTION("""COMPUTED_VALUE"""),6.12) -> 6.12 | K25: =IFERROR(__xludf.DUMMYFUNCTION("""COMPUTED_VALUE"""),3.53) -> 3.53 | L25: =IFERROR(__xludf.DUMMYFUNCTION("""COMPUTED_VALUE"""),25.0) -> 25
A26: =IFERROR(__xludf.DUMMYFUNCTION("""COMPUTED_VALUE"""),26.0) -> 26 | B26: =IFERROR(__xludf.DUMMYFUNCTION("""COMPUTED_VALUE"""),45335.0) -> 45335 | C26: =IFERROR(__xludf.DUMMYFUNCTION("""COMPUTED_VALUE"""),67.0) -> 67 | D26: =IFERROR(__xludf.DUMMYFUNCTION("""COMPUTED_VALUE"""),"#REF!") -> #REF! | F26: =IFERROR(__xludf.DUMMYFUNCTION("""COMPUTED_VALUE"""),"Chardonnnay") -> Chardonnnay | G26: =IFERROR(__xludf.DUMMYFUNCTION("""COMPUTED_VALUE"""),11.8) -> 11.8 | H26: =IFERROR(__xludf.DUMMYFUNCTION("""COMPUTED_VALUE"""),2.0) -> 2 | J26: =IFERROR(__xludf.DUMMYFUNCTION("""COMPUTED_VALUE"""),6.04) -> 6.04 | K26: =IFERROR(__xludf.DUMMYFUNCTION("""COMPUTED_VALUE"""),3.55) -> 3.55 | L26: =IFERROR(__xludf.DUMMYFUNCTION("""COMPUTED_VALUE"""),18.0) -> 18
A27: =IFERROR(__xludf.DUMMYFUNCTION("""COMPUTED_VALUE"""),27.0) -> 27 | B27: =IFERROR(__xludf.DUMMYFUNCTION("""COMPUTED_VALUE"""),45335.0) -> 45335 | C27: =IFERROR(__xludf.DUMMYFUNCTION("""COMPUTED_VALUE"""),80.0) -> 80 | F27: =IFERROR(__xludf.DUMMYFUNCTION("""COMPUTED_VALUE"""),"Chardonnay") -> Chardonnay | G27: =IFERROR(__xludf.DUMMYFUNCTION("""COMPUTED_VALUE"""),13.0) -> 13 | H27: =IFERROR(__xludf.DUMMYFUNCTION("""COMPUTED_VALUE"""),2.0) -> 2 | J27: =IFERROR(__xludf.DUMMYFUNCTION("""COMPUTED_VALUE"""),5.9) -> 5.9 | K27: =IFERROR(__xludf.DUMMYFUNCTION("""COMPUTED_VALUE"""),3.47) -> 3.47 | L27: =IFERROR(__xludf.DUMMYFUNCTION("""COMPUTED_VALUE"""),18.0) -> 18
A28: =IFERROR(__xludf.DUMMYFUNCTION("""COMPUTED_VALUE"""),28.0) -> 28 | B28: =IFERROR(__xludf.DUMMYFUNCTION("""COMPUTED_VALUE"""),45336.0) -> 45336 | C28: =IFERROR(__xludf.DUMMYFUNCTION("""COMPUTED_VALUE"""),79.0) -> 79 | D28: =IFERROR(__xludf.DUMMYFUNCTION("""COMPUTED_VALUE"""),"#REF!") -> #REF! | F28: =IFERROR(__xludf.DUMMYFUNCTION("""COMPUTED_VALUE"""),"Chardonnay") -> Chardonnay | G28: =IFERROR(__xludf.DUMMYFUNCTION("""COMPUTED_VALUE"""),12.0) -> 12 | H28: =IFERROR(__xludf.DUMMYFUNCTION("""COMPUTED_VALUE"""),2.0) -> 2 | J28: =IFERROR(__xludf.DUMMYFUNCTION("""COMPUTED_VALUE"""),6.2) -> 6.2 | K28: =IFERROR(__xludf.DUMMYFUNCTION("""COMPUTED_VALUE"""),3.45) -> 3.45 | L28: =IFERROR(__xludf.DUMMYFUNCTION("""COMPUTED_VALUE"""),12.0) -> 12
A29: =IFERROR(__xludf.DUMMYFUNCTION("""COMPUTED_VALUE"""),29.0) -> 29 | B29: =IFERROR(__xludf.DUMMYFUNCTION("""COMPUTED_VALUE"""),45336.0) -> 45336 | C29: =IFERROR(__xludf.DUMMYFUNCTION("""COMPUTED_VALUE"""),83.0) -> 83 | D29: =IFERROR(__xludf.DUMMYFUNCTION("""COMPUTED_VALUE"""),"#REF!") -> #REF! | F29: =IFERROR(__xludf.DUMMYFUNCTION("""COMPUTED_VALUE"""),"aspirant") -> aspirant
A30: =IFERROR(__xludf.DUMMYFUNCTION("""COMPUTED_VALUE"""),30.0) -> 30 | B30: =IFERROR(__xludf.DUMMYFUNCTION("""COMPUTED_VALUE"""),45339.0) -> 45339 | C30: =IFERROR(__xludf.DUMMYFUNCTION("""COMPUTED_VALUE"""),90.0) -> 90 | L30: =IFERROR(__xludf.DUMMYFUNCTION("""COMPUTED_VALUE"""),33.0) -> 33
A31: =IFERROR(__xludf.DUMMYFUNCTION("""COMPUTED_VALUE"""),31.0) -> 31 | B31: =IFERROR(__xludf.DUMMYFUNCTION("""COMPUTED_VALUE"""),45341.0) -> 45341 | C31: =IFERROR(__xludf.DUMMYFUNCTION("""COMPUTED_VALUE"""),78.0) -> 78 | G31: =IFERROR(__xludf.DUMMYFUNCTION("""COMPUTED_VALUE"""),11.5) -> 11.5 | H31: =IFERROR(__xludf.DUMMYFUNCTION("""COMPUTED_VALUE"""),2.0) -> 2 | I31: =IFERROR(__xludf.DUMMYFUNCTION("""COMPUTED_VALUE"""),0.3) -> 0.3 | J31: =IFERROR(__xludf.DUMMYFUNCTION("""COMPUTED_VALUE"""),7.3) -> 7.3 | K31: =IFERROR(__xludf.DUMMYFUNCTION("""COMPUTED_VALUE"""),3.26) -> 3.26 | L31: =IFERROR(__xludf.DUMMYFUNCTION("""COMPUTED_VALUE"""),12.0) -> 12
A32: =IFERROR(__xludf.DUMMYFUNCTION("""COMPUTED_VALUE"""),32.0) -> 32 | B32: =IFERROR(__xludf.DUMMYFUNCTION("""COMPUTED_VALUE"""),45341.0) -> 45341 | C32: =IFERROR(__xludf.DUMMYFUNCTION("""COMPUTED_VALUE"""),77.0) -> 77 | D32: =IFERROR(__xludf.DUMMYFUNCTION("""COMPUTED_VALUE"""),"1.083") -> 1.083 | E32: =IFERROR(__xludf.DUMMYFUNCTION("""COMPUTED_VALUE"""),18579.600000000002) -> 18579.6 | F32: =IFERROR(__xludf.DUMMYFUNCTION("""COMPUTED_VALUE"""),"Pedro Gimenez") -> Pedro Gimenez | H32: =IFERROR(__xludf.DUMMYFUNCTION("""COMPUTED_VALUE"""),2.25) -> 2.25
A33: =IFERROR(__xludf.DUMMYFUNCTION("""COMPUTED_VALUE"""),33.0) -> 33 | B33: =IFERROR(__xludf.DUMMYFUNCTION("""COMPUTED_VALUE"""),45341.0) -> 45341 | C33: =IFERROR(__xludf.DUMMYFUNCTION("""COMPUTED_VALUE"""),83.0) -> 83 | D33: =IFERROR(__xludf.DUMMYFUNCTION("""COMPUTED_VALUE"""),"1.108") -> 1.108 | E33: =IFERROR(__xludf.DUMMYFUNCTION("""COMPUTED_VALUE"""),47642.4) -> 47642.4 | F33: =IFERROR(__xludf.DUMMYFUNCTION("""COMPUTED_VALUE"""),"Bonarda") -> Bonarda | H33: =IFERROR(__xludf.DUMMYFUNCTION("""COMPUTED_VALUE"""),2.25) -> 2.25
A34: =IFERROR(__xludf.DUMMYFUNCTION("""COMPUTED_VALUE"""),34.0) -> 34 | B34: =IFERROR(__xludf.DUMMYFUNCTION("""COMPUTED_VALUE"""),45341.0) -> 45341 | C34: =IFERROR(__xludf.DUMMYFUNCTION("""COMPUTED_VALUE"""),67.0) -> 67 | K34: =IFERROR(__xludf.DUMMYFUNCTION("""COMPUTED_VALUE"""),3.45) -> 3.45 | L34: =IFERROR(__xludf.DUMMYFUNCTION("""COMPUTED_VALUE"""),25.0) -> 25 | M34: =IFERROR(__xludf.DUMMYFUNCTION("""COMPUTED_VALUE"""),102.0) -> 102
A35: =IFERROR(__xludf.DUMMYFUNCTION("""COMPUTED_VALUE"""),35.0) -> 35 | B35: =IFERROR(__xludf.DUMMYFUNCTION("""COMPUTED_VALUE"""),45341.0) -> 45341 | C35: =IFERROR(__xludf.DUMMYFUNCTION("""COMPUTED_VALUE"""),80.0) -> 80 | D35: =IFERROR(__xludf.DUMMYFUNCTION("""COMPUTED_VALUE"""),"1.100") -> 1.100 | E35: =IFERROR(__xludf.DUMMYFUNCTION("""COMPUTED_VALUE"""),18657.600000000002) -> 18657.6 | F35: =IFERROR(__xludf.DUMMYFUNCTION("""COMPUTED_VALUE"""),"Syrah") -> Syrah | K35: =IFERROR(__xludf.DUMMYFUNCTION("""COMPUTED_VALUE"""),3.43) -> 3.43 | L35: =IFERROR(__xludf.DUMMYFUNCTION("""COMPUTED_VALUE"""),24.0) -> 24 | M35: =IFERROR(__xludf.DUMMYFUNCTION("""COMPUTED_VALUE"""),83.0) -> 83
A36: =IFERROR(__xludf.DUMMYFUNCTION("""COMPUTED_VALUE"""),36.0) -> 36 | B36: =IFERROR(__xludf.DUMMYFUNCTION("""COMPUTED_VALUE"""),45341.0) -> 45341 | C36: =IFERROR(__xludf.DUMMYFUNCTION("""COMPUTED_VALUE"""),74.0) -> 74 | D36: =IFERROR(__xludf.DUMMYFUNCTION("""COMPUTED_VALUE"""),"1.106") -> 1.106 | E36: =IFERROR(__xludf.DUMMYFUNCTION("""COMPUTED_VALUE"""),13000.0) -> 13000 | F36: =IFERROR(__xludf.DUMMYFUNCTION("""COMPUTED_VALUE"""),"Syrah P") -> Syrah P | K36: =IFERROR(__xludf.DUMMYFUNCTION("""COMPUTED_VALUE"""),3.4) -> 3.4 | L36: =IFERROR(__xludf.DUMMYFUNCTION("""COMPUTED_VALUE"""),20.0) -> 20 | M36: =IFERROR(__xludf.DUMMYFUNCTION("""COMPUTED_VALUE"""),85.0) -> 85
A37: =IFERROR(__xludf.DUMMYFUNCTION("""COMPUTED_VALUE"""),37.0) -> 37 | B37: =IFERROR(__xludf.DUMMYFUNCTION("""COMPUTED_VALUE"""),45341.0) -> 45341 | C37: =IFERROR(__xludf.DUMMYFUNCTION("""COMPUTED_VALUE"""),81.0) -> 81 | K37: =IFERROR(__xludf.DUMMYFUNCTION("""COMPUTED_VALUE"""),3.39) -> 3.39 | L37: =IFERROR(__xludf.DUMMYFUNCTION("""COMPUTED_VALUE"""),23.0) -> 23 | M37: =IFERROR(__xludf.DUMMYFUNCTION("""COMPUTED_VALUE"""),92.0) -> 92
A38: =IFERROR(__xludf.DUMMYFUNCTION("""COMPUTED_VALUE"""),38.0) -> 38 | B38: =IFERROR(__xludf.DUMMYFUNCTION("""COMPUTED_VALUE"""),45341.0) -> 45341 | C38: =IFERROR(__xludf.DUMMYFUNCTION("""COMPUTED_VALUE"""),66.0) -> 66 | K38: =IFERROR(__xludf.DUMMYFUNCTION("""COMPUTED_VALUE"""),3.5) -> 3.5 | L38: =IFERROR(__xludf.DUMMYFUNCTION("""COMPUTED_VALUE"""),26.0) -> 26 | M38: =IFERROR(__xludf.DUMMYFUNCTION("""COMPUTED_VALUE"""),102.0) -> 102
A39: =IFERROR(__xludf.DUMMYFUNCTION("""COMPUTED_VALUE"""),39.0) -> 39 | B39: =IFERROR(__xludf.DUMMYFUNCTION("""COMPUTED_VALUE"""),45341.0) -> 45341 | C39: =IFERROR(__xludf.DUMMYFUNCTION("""COMPUTED_VALUE"""),82.0) -> 82 | K39: =IFERROR(__xludf.DUMMYFUNCTION("""COMPUTED_VALUE"""),3.4) -> 3.4 | L39: =IFERROR(__xludf.DUMMYFUNCTION("""COMPUTED_VALUE"""),25.0) -> 25 | M39: =IFERROR(__xludf.DUMMYFUNCTION("""COMPUTED_VALUE"""),110.0) -> 110
A40: =IFERROR(__xludf.DUMMYFUNCTION("""COMPUTED_VALUE"""),40.0) -> 40 | B40: =IFERROR(__xludf.DUMMYFUNCTION("""COMPUTED_VALUE"""),45341.0) -> 45341 | C40: =IFERROR(__xludf.DUMMYFUNCTION("""COMPUTED_VALUE"""),65.0) -> 65 | K40: =IFERROR(__xludf.DUMMYFUNCTION("""COMPUTED_VALUE"""),3.5) -> 3.5 | L40: =IFERROR(__xludf.DUMMYFUNCTION("""COMPUTED_VALUE"""),27.0) -> 27 | M40: =IFERROR(__xludf.DUMMYFUNCTION("""COMPUTED_VALUE"""),90.0) -> 90
...

Sheet ANALISIS IMPRESION
A1: ID Analisis Impresion | B1: Fecha | C1: Observaciones | D1: Fecha Generacion
A2: 5f9ee4d1 | B2: 45757 | C2: Control Bodega
A3: b3c6eef9 | B3: 45761 | C3: Control Arqueo
A4: f9997bec | B4: 45762 | C4: Visita Victoria
A5: db8f646a | B5: 45764 | C5: Visita Victoria
A6: ffa52fc7 | B6: 45770 | C6: Control Arqueo 23/4/25
A7: c7e3a881 | B7: 45771 | C7: Visita Victoria
A8: a143bd0e | B8: 45777 | C8: Visita Victoria
A9: 3326a654 | B9: 45782 | C9: Control Arqueo 05/May
A10: 4aa90bdd | B10: 45778 | C10: PRUEBA ORDENADAS
A11: 3e08ac4a | B11: 45784 | C11: Visita Victoria
A12: b8c7d185 | B12: 45779 | C12: prueba calificacion
A13: d1ac56f6 | B13: 45787 | C13: Arqueo control 10/05/25
... A32: c4ac1700 | B32: 45881 | C32: Visita Victoria 12/08/25

Sheet CORTE TEORICO
A1: ID Corte Teorico | B1: Fecha | C1: Nombre Corte | D1: Observaciones
A2: a70dcd0c | B2: 45763 | C2: Corte prueba
A3: e48892a3 | B3: 45764 | C3: Bonarda Baudron
A4: f47d7c5e | B4: 45768 | C4: Malbec Tecnovitis | D4: Tinto con numero de Malbec
A5: 3e8987e7 | B5: 45775 | C5: Malbec Millan 233
A6: d8d61385 | B6: 45775 | C6: Malbec Millan 200k
A7: 192efacd | B7: 45777 | C7: vino con azucar
A8: 46fdd27a | B8: 45791 | C8: Chardonnay proporcional
A9: 795f8f7d | B9: 45798 | C9: corte malbec
A10: df7dc1bc | B10: 45820 | C10: Blanco Aromatico
A11: 105c2713 | B11: 45841 | C11: Malbec Corte general
A12: 76a5f033 | B12: 45848 | C12: Malbec Lopez
A13: 697c9a77 | B13: 45848 | C13: Tinto Lopez

Sheet CORTE TEORICO DETALLE
A1: ID Detalle Corte Teorico | B1: Corte Teorico | C1: Volumen al Corte | D1: Pileta | E1: Lote Pileta | F1: Varietal | G1: Volumen Actual | H1: ALC | I1: AC VOL | J1: AC T | K1: PH | L1: SO2L | M1: SO2T
A2: 56ce5437 | B2: a70dcd0c | C2: 36501 | D2: 15 | E2: f764d2d1 | F2: Malbec | G2: 36500 | H2: 12.7 | I2: 0.38 | J2: 5.4 | K2: 3.77 | L2: 14 | M2: 70
A3: b2f5b04b | B3: a70dcd0c | C3: 29001 | D3: 46 | E3: 92bbed34 | F3: Malbec Gota | G3: 29000 | H3: 13.1 | I3: 0.38 | J3: 6.97 | K3: 3.57 | L3: 35 | M3: 101
A4: 8dd4d002 | B4: a70dcd0c | C4: 25002 | D4: 121 | E4: 5c542a1f | F4: Malbec Mec | G4: 85800 | H4: 13.2 | I4: 0.4 | J4: 4.72 | K4: 3.74 | L4: 16 | M4: 51
A5: 953e3d1a | B5: a70dcd0c | C5: 34998 | D5: 25 | E5: a6d28e88 | F5: Syrah | G5: 194300 | H5: 14 | I5: 0.54 | J5: 6.1 | K5: 3.75 | L5: 33 | M5: 101
A6: 8f04eec7 | B6: e48892a3 | C6: 35801 | D6: 34 | E6: 7b6b2c2a | F6: Bonarda | G6: 35800 | H6: 13.3 | I6: 0.51 | J6: 6.67 | K6: 3.69 | L6: 26 | M6: 96
A8: c0d5ccb3 | B8: e48892a3 | C8: 30001 | D8: 127 | E8: 91eadabd | F8: Criolla s/Bonarda | G8: 30000 | H8: 14.3 | I8: 0.57 | J8: 5.55 | K8: 3.83 | L8: 11 | M8: 55
A9: 4d1f3ac3 | B9: e48892a3 | C9: 45000 | D9: 24 | E9: 7efc7da2 | F9: Bonarda C2 | G9: 186600 | H9: 12.8 | I9: 0.62 | J9: 5.1 | K9: 3.89 | L9: 30 | M9: 92
A12: e6d0a217 | B12: f47d7c5e | C12: 30000 | D12: 104 | E12: 1d042bcb | F12: Tinto | G12: 30000 | H12: 13.2 | I12: 0.42 | J12: 5.92 | K12: 3.77 | L12: 18 | M12: 77
A13: 9ab7f8cd | B13: f47d7c5e | C13: 30000 | D13: 24 | E13: 7efc7da2 | F13: Bonarda C2 | G13: 186600 | H13: 12.8 | I13: 0.62 | J13: 5.1 | K13: 3.89 | L13: 30 | M13: 92
A14: 4c5b61ec | B14: 3e8987e7 | C14: 149100 | D14: 24 | E14: 7efc7da2 | F14: Bonarda C2 | G14: 185000 | H14: 12.8 | I14: 0.62 | J14: 5.1 | K14: 3.89 | L14: 30 | M14: 92
A15: 13ec972a | B15: 3e8987e7 | C15: 37280 | D15: 118 | E15: 8ec426a5 | F15: Bonarda | G15: 155000 | H15: 13 | I15: 0.31 | J15: 6.37 | L15: 23
A16: 24c7878a | B16: 3e8987e7 | C16: 46600 | D16: 114 | E16: e53d4606 | F16: Syrah | G16: 125300 | H16: 13.5 | I16: 0.48 | J16: 6.52 | K16: 3.59 | L16: 32 | M16: 96
A17: 4b011795 | B17: d8d61385 | C17: 86000 | D17: 114 | E17: e53d4606 | F17: Syrah | G17: 125300 | H17: 13.5 | I17: 0.48 | J17: 6.52 | K17: 3.59 | L17: 32 | M17: 96
